[2024-02-27 12:49:44,424] [14732] [app_log] [authentication_untils.py:68] [authentication_untils:send_sms_to_number] [INFO]- 发送短信成功，手机号为15863027613，验证码为6970
[2024-02-27 12:49:44,429] [14732] [app_log] [authentication_untils.py:89] [authentication_untils:send_sms_to_number] [ERROR]- 发送短信失败，手机号为15863027613，验证码为6970. 原因：BasicKeyCommands.setex() got an unexpected keyword argument 'timeout'
[2024-02-27 12:51:52,732] [21484] [app_log] [authentication_untils.py:68] [authentication_untils:send_sms_to_number] [INFO]- 发送短信成功，手机号为15863027613，验证码为3842
[2024-02-27 12:53:14,326] [21484] [app_log] [authentication_untils.py:68] [authentication_untils:send_sms_to_number] [INFO]- 发送短信成功，手机号为15863027613，验证码为1938
[2024-02-27 12:53:14,327] [21484] [app_log] [authentication_untils.py:89] [authentication_untils:send_sms_to_number] [ERROR]- 发送短信失败，手机号为15863027613，验证码为1938. 原因：can only concatenate str (not "int") to str
[2024-02-27 12:57:38,574] [22708] [app_log] [authentication_untils.py:68] [authentication_untils:send_sms_to_number] [INFO]- 发送短信成功，手机号为15863027613，验证码为4723
[2024-02-27 12:57:38,575] [22708] [app_log] [authentication_untils.py:89] [authentication_untils:send_sms_to_number] [ERROR]- 发送短信失败，手机号为15863027613，验证码为4723. 原因：BasicKeyCommands.setex() got an unexpected keyword argument 'timeout'
[2024-02-27 13:00:41,881] [15768] [app_log] [authentication_untils.py:85] [authentication_untils:send_sms_to_number] [INFO]- 发送短信成功，手机号为15863027613，验证码为2194
[2024-02-27 13:01:18,153] [15768] [app_log] [authentication_untils.py:85] [authentication_untils:send_sms_to_number] [INFO]- 发送短信成功，手机号为15863027613，验证码为3521
[2024-02-27 13:03:14,263] [18472] [app_log] [authentication_untils.py:85] [authentication_untils:send_sms_to_number] [INFO]- 发送短信成功，手机号为15863027613，验证码为2978
[2024-02-27 13:12:38,204] [17528] [app_log] [authentication_untils.py:85] [authentication_untils:send_sms_to_number] [INFO]- 发送短信成功，手机号为15863027613，验证码为6498
[2024-02-27 13:12:59,618] [17528] [app_log] [user.py:39] [user:register] [ERROR]- 15863027613 注册用户失败，(pymysql.err.IntegrityError) (1062, "Duplicate entry '15863027613' for key 'ix_users_mobile'")
[SQL: INSERT INTO users (username, password, mobile, nickname, gender, birthday, email, brief, avatar, status, `admin`) VALUES (%(username)s, %(password)s, %(mobile)s, %(nickname)s, %(gender)s, %(birthday)s, %(email)s, %(brief)s, %(avatar)s, %(status)s, %(admin)s)]
[parameters: {'username': 'thsh', 'password': '123456', 'mobile': '15863027613', 'nickname': None, 'gender': None, 'birthday': None, 'email': None, 'brief': None, 'avatar': None, 'status': 0, 'admin': 0}]
(Background on this error at: https://sqlalche.me/e/14/gkpj)
[2024-02-27 13:22:15,134] [17528] [app_log] [authentication_untils.py:85] [authentication_untils:send_sms_to_number] [INFO]- 发送短信成功，手机号为15863027613，验证码为8312
[2024-02-27 14:42:32,569] [23400] [app_log] [authentication_untils.py:88] [authentication_untils:send_sms_to_number] [INFO]- 发送短信成功，手机号为15863027613，验证码为1065
